Workbook

Sheet WEALTH

Sheet AGENDA
A1: Financial Needs Analysis (FNA) - LFS Step 5 & Filter 7
A2: Goal: Strategic Diversification based on Suitability, Affordability and Long Term Planning
A3: We provide Solutions to Client based on three things 1.Need or Purpose, 2.Risk-Apetite and 3.Time-Horizon
A4: Note: Both husband and wife are recommended to attend this important session
A6: Set Agenda to Client what to expect from this exercise
A7: By the end of the exercise, you will have the clarity on the following
A8: 1. What are your financial goals between now and rest of the life?
A9: 2. Are your properly diversified? Are you getting the right rate of return?
A10: 3. Any Tax Implications Now, during Retirement, and during Legacy Transfer of Assets?
A11: 4. Are you on Track to meet your financial goals?
A13: Provide these disclaimers to Client (as needed)
A14: 1. I will gather some information to understand your situation better
... A17: 4. Is that okay? shall we go ahead?

Sheet ASSETS
A1: NAME: | E1: DATE: | F1: 45189
A2: NOTE: 1. START WITH 'Y & N' IN B & C > 2. COMPLETE FINANCIAL_GOALS > 3. COMPLETE 'E & F' IN FINANCIAL_ASSETS > 4. COMPLE 'F' IN FINANCIAL_GOALS > 4. COMPLETE CLIENT_INFO SHEET
A3: RETIREMENT PLANNING (USA) | B3: HIM (Y/N) | C3: HER (Y/N) | D3: NOTES | E3: PRESENT VALUE | F3: PROJECTED VALUE @ 65
A4: CURRENT 401K / 403B
A5: COMPANY MATCH % | D5: COMPOUND CALC (USE ~4% or 5% RATE) | E5: N/A | F5: N/A
A6: ARE YOU MAX FUNDING (~$22.5K)
A7: PREVIOUS 401K / ROLLOVER 401K
A8: TRADITIONAL IRA / SEP-IRA [TAX-DEFERRED]
A9: ROTH IRA / ROTH 401K [TAX-FREE]
A10: PENSION / ESPP / ANNUITIES
A12: REAL ESTATE INVESTMENTS (USA) | B12: HIM (Y/N) | C12: HER (Y/N) | D12: NOTES | E12: PRESENT VALUE | F12: PROJECTED VALUE @ 65
A13: PERSONAL HOME
A14: REAL ESTATE PROPERTIES / RENTALS
A15: REAL ESTATE LAND PARCELS
A16: INHERITANCE IN THE USA
A18: STOCKS / BUSINESS / INCOME (USA) | B18: HIM (Y/N) | C18: HER (Y/N) | D18: NOTES | E18: PRESENT VALUE | F18: PROJECTED VALUE @ 65
A19: STOCKS / MFs / BONDS / ETFs (OUTSIDE OF 401K)
A20: DO YOU OWN A BUSINESS
A21: OTHE / ALTERNATIVE INVESTMENTS (PRIVATE EQUITY, CROWD FUNDING, ETC.,)
A22: CERTIFICATE OF DEPOSITS (BANK CDs)
A23: CASH IN BANK + EMERGENCY FUND | B23: Y | C23: Y
A24: ANNUAL HOUSE-HOLD INCOME | B24: Y | C24: Y | E24: N/A | F24: N/A
A25: ANNUAL SAVINGS GOING FORWARD | B25: Y | C25: Y | E25: N/A
A26: (PAY YOURSELF FIRST - EXAMPLE: SAVE 25% OF SINGLE INCOME OR SAVE 50% OF DOUBLE INCOME… OR HELP WITH BUDGETING
A27: FAMILY PROTECTION & INSURANCE | B27: HIM (Y/N) | C27: HER (Y/N) | D27: NOTES | E27: PRESENT CASH VALUE | F27: FUTURE LEGACY VALUE
A28: LIFE INSURANCE AT WORK | E28: N/A | F28: N/A
A29: LIFE INSURANCE OUTSIDE WORK | E29: N/A
A30: IS IT CASH VALUE LIFE INSURANCE?
A31: WHICH COMPANY? HOW LONG? | B31: N/A | C31: N/A | E31: N/A | F31: N/A
A32: SHORT TERM / LONG TERM DISABILITY AT WORK | E32: N/A | F32: N/A
A33: LONG TERM CARE OUTSIDE OF WORK | E33: N/A | F33: N/A
A34: HEALTH SAVINGS ACCOUNT (HSA)
A35: MORTGAGE PROTECTION INSURANCE | E35: N/A | F35: N/A
A37: COLLEGE PLANNING / ESTATE PLANNING | B37: CHILD1 | C37: CHILD2 | D37: NOTES | E37: PRESENT VALUE | F37: PROJECTED VALUE
A38: 529 PLANS / STATE PRE-PAID PLANS
A39: WILL & TRUST (ESTATE PLANNING) | E39: N/A | F39: N/A
A41: FOREIGN FINANCIAL ASSETS (OUTSIDE OF THE USA) | B41: HIM (Y/N) | C41: HER (Y/N) | D41: NOTES | E41: PRESENT VALUE | F41: PROJECTED VALUE @ 65
A42: REAL ESATE ASSETS
A43: OTHE ASSETS (FIXED DEPOSITS, STOCKS, LOANS, JEWELLERY, INVESTMENTS)
A45: PRESENT VALUE & FUTURE PROJECTED VALUE @ 65 | E45: =SUM(E4:E43) -> 0 | F45: =SUM(F4:F43) -> 0
...

Sheet GOALS
A1: FINANCIAL GOALS & PLANNING NAME: | B1: =ASSETS!B1 | E1: DATE: | F1: 45779
A2: KIDS COLLEGE PLANNING | B2: YEARS FROM TODAY | C2: BEGIN YEAR | D2: END YEAR | E2: AMOUNT | F2: PLAN
A3: CHILD 1 (NAME / AGE): 10 | C3: =YEAR($F$1)+B3 -> 2025 | D3: =C3+4 -> 2029
A4: CHILD 2 (NAME / AGE): | C4: =YEAR($F$1)+B4 -> 2025 | D4: =C4+4 -> 2029
A5: VANGUARD COLLEGE SAVINGS PLANNER (IF NEEDED)
A6: KIDS WEDDING PLANNING | B6: YEARS FROM TODAY | C6: YEAR | E6: AMOUNT | F6: PLAN
A7: =A3 -> CHILD 1 (NAME / AGE): 10 | C7: =YEAR($F$1)+B7 -> 2025
A8: =A4 -> CHILD 2 (NAME / AGE): | C8: =YEAR($F$1)+B8 -> 2025
A10: RETIREMENT PLANNING | C10: BEGIN YEAR | D10: END YEAR | E10: AMOUNT | F10: PLAN
A11: NUMBER OF YEARS TO RETIREMENT AGE OF 65 | C11: N/A | D11: N/A | E11: N/A | F11: 401K/IRA = $
A12: NUMBER OF YEARS IN RETIREMENT (~UNTIL AGE 85 OR 90) | C12: =YEAR($F$1)+B11 -> 2025 | D12: =YEAR($F$1)+B11+B12 -> 2025 | F12: SSA = $
A13: MONTHLY INCOME NEEDED IN TODAY'S DOLLARS (PRE-TAX) (INCLUDE PROPERTY TAXES + CARS + INSURANCES + FOOD + REPAIRS + UTILITIES + LIVING EXPENSES) | C13: RETIREMENT WITHDRAWL CALCULATOR | F13: PENSION = $
A14: MONTHLY RETIREMENT INCOME @ 65 w-INFLATION 3% | B14: =FV(0.03,B11,0,-B13) -> 0 | C14: N/A | F14: RENTAL = $
A15: ANNUAL RETIREMENT INCOME @ 65 w-INFLATION 3% | B15: =B14*12 -> 0 | C15: =YEAR($F$1)+B11 -> 2025 | D15: =YEAR($F$1)+B11+B12 -> 2025 | E15: =B15*B12 -> 0
A17: HEALTH CARE AND LONG TERM CARE PLANNING | B17: NOTES | C17: BEGIN YEAR | D17: END YEAR | E17: AMOUNT | F17: PLAN
A18: HEALTH CARE OUT-OF-POCKET EXPENSES (PLAN FOR ~20+ YRS) (DOCTORS CO-PAYS, LABS CO-PAYS, PHARMACY CO-PAYS ETC.,) | B18: ~$315K FOR COUPLE IN TODAY'S DOLLARS (ADD 3% INFLATION FOR FUTURE) | C18: =YEAR($F$1)+B11 -> 2025 | D18: =YEAR($F$1)+B11+B12 -> 2025
A19: LONG TERM CARE / DISABILITY (PLAN FOR ATLEAST 2+ YRS EACH) (AVERAGE PERSON STAYS IN LTC BETWEEN 0 TO 5 YEARS) | B19: ~$10K PER MONTH x 24 MONTHS x 2 PEOPLE | C19: =YEAR($F$1)+B11 -> 2025 | D19: =YEAR($F$1)+B11+B12 -> 2025
A21: LIFE GOALS PLANNING | B21: NOTES | C21: BEGIN YEAR | D21: END YEAR | E21: AMOUNT | F21: PLAN
A22: TRAVEL BUDGET (TRAVEL TO INDIA, TO KIDS, WORLD TRAVEL) | C22: =YEAR($F$1)+B11 -> 2025 | D22: =YEAR($F$1)+B11+B12 -> 2025
A23: VACATION HOME / FARM HOUSE / NEW LUXURY HOME | C23: 2023 | D23: N/A
A24: CHARITY FOUNDATION / OLD AGE HOME / TEMPLE ETC., | D24: N/A
A25: ANY OTHER LIFE GOALS (BOAT / RV / LUXURY CAR / JEWELLERY etc.,
A27: LEGACY PLANNING | B27: NOTES | C27: YEAR | D27: YEAR | E27: AMOUNT | F27: PLAN
A28: FUND FOR KIDS PRIMARY HOME OR BUSINESS | C28: =C7 -> 2025 | D28: =C8 -> 2025
A29: LEGACY ASSET FOR KIDS / FAMILY (FINAL ASSETS LIKE PRIMARY HOME + REAL ESTATE + LIFE INSURANCE) | C29: N/A
A30: RETIRE PARENTS OR SPECIAL NEEDS KIDS / FAMILY | C30: 2022 | D30: 2060
A32: TOTAL REQUIREMENT | E32: =SUM(E3:E31) -> 0
A33: PROJECTED ASSET VALUE AT AGE 65 (USA AND OFF-SHORE) | E33: =SUM(ASSETS!F4:F43) -> 0
A34: DISCLAIMER: FOR EDUCATION PURPOSE ONLY. WE DO NOT PROVIDE LEGAL OR TAX ADVICE

Sheet SUMMARY
B1: NAME | C1: GENDER | D1: DOB | E1: PHONE | F1: EMAIL | G1: WORKING (Y/N) | H1: IMMIGRATION
A2: HUSBAND
A3: WIFE
A4: CHILD 1
A5: CHILD 2
A6: CITY & STATE
A8: FUNDING SOURCES FOR CREATING PLANS BASED ON FINANCIAL GOALS
A9: SAVINGS | B9: SOURCE OF FUNDS | C9: AMOUNT | D9: AMOUNT AVAILABLE TO CREATE PLANS | F9: NOTES
A10: EXISTING SAVINGS | B10: CASH IN BANK (OUTSIDE THE USA) | C10: =E34
A11: EXISTING SAVINGS | B11: CASH IN BANK (USA) | C11: =SUM(ASSETS!E22:E23) -> 0
A12: EXISTING SAVINGS | B12: 401K / IRA ROLLOVER | C12: =SUM(ASSETS!E7:E9) -> 0
A13: EXISTING SAVINGS | B13: STOCK MARKET INVESTMENTS | C13: =ASSETS!E19
A14: PROGRESSIVE SAVINGS | B14: ANNUAL SAVINGS | C14: =SUM(ASSETS!D25) -> 0
A15: PROGRESSIVE SAVINGS | B15: ANNUAL OVER FUNDING IN 401K
A16: PROGRESSIVE SAVINGS | B16: ANNUAL RENTAL INCOME
A17: PROGRESSIVE SAVINGS | B17: ANNUAL 529 CONTRIBUTIONS
B18: TOTAL AMOUNT | C18: =SUM(C10:C17) -> 0 | D18: =SUM(D10:D17) -> 0
A19: DISCLAIMER: FOR EDUCATION PURPOSE ONLY. WE DO NOT PROVIDE LEGAL OR TAX ADVICE
A21: NOTES & SUMMARY | B21: GOALS: DIVERSIFICATION, COMPOUNDING GROWTH, MARKET SAFETY, TAX ADVANTAGES, ASSET PROTECTION
B22: PROTECTION PLANNING:
B23: LONG TERM CARE PLANNING:
B24: WILL & TRUST / ESTATE PLANNING:
B25: OPTIONS FOR 401K/IRA ROLLOVER ($):
B26: OPTIONS FOR ANNUAL SAVINGS ($):
B27: OPTIONS FOR CASH IN BANK ($):
B28: OPTIONS FOR CASH IN STOCKS ($):
